Workbook

Sheet Basic Pivot 
E1: Retailer | F1: Total Sales | H1: Sales Method | I1: Total Sales | J1: Percentage | K1: Retailer | L1: Total Sales | N1: Product category | O1: Total Sales | P1: Percentage by year | Q1: Units Sold | R1: Percentage of units | S1: 2020 | T1: Jan | U1: 2312746 | W1: Region | X1: Total Sales | Z1: State | AA1: Total Sales | AC1: City | AD1: Total Sales | AE1: 2020 | AF1: Retailer | AG1: Operating Profit
D2: 2020 | E2: Foot Locker | F2: 5748880 | G2: 2020 | H2: In-store | I2: 9390300 | J2: 0.38743137 | K2: Amazon | L2: 10096987 | M2: 2020 | N2: Men's Apparel | O2: 3495339 | P2: 0.14421307 | Q2: 61227 | R2: 0.13242594 | T2: Feb | U2: 2140813 | V2: 2020 | W2: West | X2: 10018403 | Y2: 2020 | Z2: California | AA2: 1246140 | AB2: 2020 | AC2: Denver | AD2: 2569036 | AF2: Foot Locker | AG2: 2223626.9
A3: Region | B3: Sum of Total Sales | E3: Kohl's | F3: 92503 | H3: Online | I3: 4519966 | J3: 0.18648782 | K3: Foot Locker | L3: 29024945 | N3: Men's Athletic Footwear | O3: 4237587 | P3: 0.17483724 | Q3: 81760 | R3: 0.17683611 | T3: Mar | U3: 2474202 | W3: Northeast | X3: 5811259 | Z3: Colorado | AA3: 2569036 | AC3: Houston | AD3: 3629632 | AF3: Kohl's | AG3: 39003.67
A4: Midwest | B4: 16674434 | E4: Sports Direct | F4: 1988351 | H4: Outlet | I4: 10327059 | J4: 0.42608081 | K4: Kohl's | L4: 13512453 | N4: Men's Street Footwear | O4: 4991020 | P4: 0.20592289 | Q4: 99186 | R4: 0.21452626 | T4: Apr | U4: 3193081 | W4: Southeast | X4: 3874113 | Z4: Florida | AA4: 3874113 | AC4: Las Vegas | AD4: 2981134 | AF4: Sports Direct | AG4: 801740.29
A5: Northeast | B5: 25078267 | E5: Walmart | F5: 4703975 | G5: 2021 | H5: In-store | I5: 26274075 | J5: 0.27388992 | K5: Sports Direct | L5: 24616622 | N5: Women's Apparel | O5: 4692707 | P5: 0.19361489 | Q5: 80208 | R5: 0.17347934 | T5: May | U5: 2164764 | W5: South | X5: 3629632 | Z5: Minnesota | AA5: 903918 | AC5: Miami | AD5: 3874113 | AF5: Walmart | AG5: 1857130.8
A6: South | B6: 20603356 | E6: West Gear | F6: 11703616 | H6: Online | I6: 40445691 | J6: 0.42161968 | K6: Walmart | L6: 10506085 | N6: Women's Athletic Footwear | O6: 3154892 | P6: 0.13016667 | Q6: 64177 | R6: 0.1388064 | T6: Jun | U6: 1084194 | W6: Midwest | X6: 903918 | Z6: Nevada | AA6: 2981134 | AC6: Minneapolis | AD6: 903918 | AF6: West Gear | AG6: 4094003.5
A7: Southeast | B7: 21374436 | D7: 2021 | E7: Amazon | F7: 10096987 | H7: Outlet | I7: 29209559 | J7: 0.3044904 | K7: West Gear | L7: 32409558 | N7: Women's Street Footwear | O7: 3665780 | P7: 0.15124524 | Q7: 75791 | R7: 0.16392595 | T7: Jul | U7: 2182388 | V7: 2021 | W7: West | X7: 26417754 | Z7: New York | AA7: 5676160 | AC7: New York | AD7: 5676160 | AE7: 2021 | AF7: Amazon | AG7: 3984432.1
A8: West | B8: 36436157 | E8: Foot Locker | F8: 23276065 | G8: Top 2020 | H8: =_xlfn.XLOOKUP(I8, I2:I4, H2:H4) -> Outlet | I8: =MAX(I2:I4) -> 10327059 | K8: Grand Total | L8: 120166650 | M8: 2021 | N8: Men's Apparel | O8: 13025293 | P8: 0.1357801 | Q8: 245456 | R8: 0.12172305 | T8: Aug | U8: 2641630 | W8: Northeast | X8: 19267008 | Z8: Pennsylvania | AA8: 135099 | AC8: Philadelphia | AD8: 135099 | AF8: Foot Locker | AG8: 9093400.4
A9: Total Result | B9: 120166650 | E9: Kohl's | F9: 13419950 | G9: Top 2021 | H9: =_xlfn.XLOOKUP(I9, I5:I7, H5:H7) -> Online | I9: =MAX(I5:I7) -> 40445691 | N9: Men's Athletic Footwear | O9: 16339593 | P9: 0.17032949 | Q9: 353766 | R9: 0.17543461 | T9: Sep | U9: 2367686 | W9: Southeast | X9: 17500323 | Z9: Texas | AA9: 3629632 | AC9: San Francisco | AD9: 1246140 | AF9: Kohl's | AG9: 5143256.4
E10: Sports Direct | F10: 22628271 | G10: Total | H10: In-store | I10: 35664375 | J10: 0.29679096 | N10: Men's Street Footwear | O10: 22689749 | P10: 0.23652568 | Q10: 494134 | R10: 0.24504392 | T10: Oct | U10: 1428569 | W10: South | X10: 16973724 | Z10: Washington | AA10: 3222093 | AC10: Seattle | AD10: 3222093 | AF10: Sports Direct | AG10: 9839868.4
E11: Walmart | F11: 5802110 | H11: Online | I11: 44965657 | J11: 0.37419415 | N11: Women's Apparel | O11: 19178278 | P11: 0.19992091 | Q11: 353619 | R11: 0.17536171 | T11: Nov | U11: 1168050 | W11: Midwest | X11: 15770516 | Y11: 2021 | Z11: Alabama | AA11: 2513424 | AB11: 2021 | AC11: Albany | AD11: 2994304 | AF11: Walmart | AG11: 2045618.1
E12: West Gear | F12: 20705942 | H12: Outlet | I12: 39536618 | J12: 0.3290149 | N12: Women's Athletic Footwear | O12: 11160629 | P12: 0.1163422 | Q12: 253059 | R12: 0.12549343 | T12: Dec | U12: 1079202 | V12: Top Region 2020 | W12: =_xlfn.XLOOKUP(X12,X2:X6, W2:W6) -> West | X12: =MAX(X2:X6) -> 10018403 | Z12: Alaska | AA12: 1810428 | AC12: Albuquerque | AD12: 2824641 | AF12: West Gear | AG12: 8102887.2
E13: Retailer | F13: Total Sales | G13: Top Method | H13: =_xlfn.XLOOKUP(MAX(I10:I12), I10:I12, H10:H12) -> Online | N13: Women's Street Footwear | O13: 13535783 | P13: 0.14110162 | Q13: 316478 | R13: 0.15694328 | S13: 2021 | T13: Jan | U13: 7432021 | V13: Top Region 2021 | W13: =_xlfn.XLOOKUP(X13,X7:X11, W7:W11) -> West | X13: =MAX(X7:X11) -> 26417754 | Z13: Arizona | AA13: 2254096 | AC13: Anchorage | AD13: 1810428 | AE13: Top profit retailer 2020 | AF13: =_xlfn.XLOOKUP(AG13,AG2:AG6,AF2:AF6) -> West Gear | AG13: =MAX(AG2:AG6) -> 4094003.5
D14: 2020 | E14: Foot Locker | F14: 5748880 | M14: Top product 2020 by sales | N14: =_xlfn.XLOOKUP(O14,O2:O7,N2:N7) -> Men's Street Footwear | O14: =MAX(O2:O7) -> 4991020 | P14: Top product 2020 by Units | Q14: =_xlfn.XLOOKUP(R14, Q2:Q7, N2:N7) -> Men's Street Footwear | R14: =MAX(Q2:Q7) -> 99186 | T14: Feb | U14: 6123040 | V14: Total | W14: West | X14: 36436157 | Z14: Arkansas | AA14: 1802672 | AC14: Atlanta | AD14: 2708591 | AE14: Top profit retailer 2021 | AF14: =_xlfn.XLOOKUP(AG14,AG7:AG12,AF7:AF12) -> Sports Direct | AG14: =MAX(AG7:AG12) -> 9839868.4
E15: Kohl's | F15: 92503 | M15: Top product 2021 by sales | N15: =_xlfn.XLOOKUP(O15, O8:O13, N8:N13) -> Men's Street Footwear | O15: =MAX(O8:O13) -> 22689749 | P15: Top product 2021 by Units | Q15: =_xlfn.XLOOKUP(R15, Q8:Q13, N8:N13) -> Men's Street Footwear | R15: =MAX(Q8:Q13) -> 494134 | T15: Mar | U15: 5220782 | W15: Northeast | X15: 25078267 | Z15: California | AA15: 7334368 | AC15: Baltimore | AD15: 951134
E16: Sports Direct | F16: 1988351 | M16: Total | N16: Men's Apparel | O16: 306683 | P16: 0.12371932 | T16: Apr | U16: 6498339 | W16: Southeast | X16: 21374436 | Z16: Connecticut | AA16: 1646448 | AC16: Billings | AD16: 1930761
E17: Walmart | F17: 4703975 | H17: Retailer | I17: Profit | N17: Men's Athletic Footwear | O17: 435526 | P17: 0.17569602 | T17: May | U17: 8576956 | W17: South | X17: 20603356 | Z17: Delaware | AA17: 1508537 | AC17: Birmingham | AD17: 2513424
E18: West Gear | F18: 11703616 | H18: Amazon | I18: 3984432.1 | N18: Men's Street Footwear | O18: 593320 | P18: 0.23935186 | T18: Jun | U18: 8718953 | W18: Midwest | X18: 16674434 | Z18: Florida | AA18: 3946476 | AC18: Boise | AD18: 2742753
D19: 2021 | E19: Amazon | F19: 10096987 | H19: Foot Locker | I19: 11317027 | N19: Women's Apparel | O19: 433827 | P19: 0.17501062 | T19: Jul | U19: 10368031 | Z19: Georgia | AA19: 2708591 | AC19: Boston | AD19: 1578435
E20: Foot Locker | F20: 23276065 | H20: Kohl's | I20: 5182260.1 | N20: Women's Athletic Footwear | O20: 317236 | P20: 0.12797652 | T20: Aug | U20: 9651596 | Z20: Hawaii | AA20: 2734457 | AC20: Burlington | AD20: 2041598
E21: Kohl's | F21: 13419950 | H21: Sports Direct | I21: 10641609 | N21: Women's Street Footwear | O21: 392269 | P21: 0.15824566 | T21: Sep | U21: 8037898 | Z21: Idaho | AA21: 2742753 | AC21: Charlotte | AD21: 2936581
E22: Sports Direct | F22: 22628271 | H22: Walmart | I22: 3902748.9 | T22: Oct | U22: 7110189 | Z22: Illinois | AA22: 1204063 | AC22: Cheyenne | AD22: 2282342
E23: Walmart | F23: 5802110 | H23: West Gear | I23: 12196891 | T23: Nov | U23: 7855390 | Z23: Indiana | AA23: 1084723 | AC23: Chicago | AD23: 1204063
E24: West Gear | F24: 20705942 | H24: Top | I24: =_xlfn.XLOOKUP(MAX(I18:I23), I18:I23, H18:H23) -> West Gear | T24: Dec | U24: 10336130 | Z24: Iowa | AA24: 909811 | AC24: Columbus | AD24: 2269283
D25: Top 2020 | E25: =_xlfn.XLOOKUP(F25, F2:F6, E2:E6) -> West Gear | F25: =MAX(F2:F6) -> 11703616 | Z25: Kansas | AA25: 1225314 | AC25: Dallas | AD25: 2982739
D26: Top 2021 | E26: =_xlfn.XLOOKUP(F26, F7:F12, E7:E12) -> Foot Locker | F26: =MAX(F7:F12) -> 23276065 | Z26: Kentucky | AA26: 1241148 | AC26: Des Moines | AD26: 909811
Z27: Louisiana | AA27: 3377031 | AC27: Detroit | AD27: 2287283
F28: Online | G28: Outlet | Z28: Maine | AA28: 1129728 | AC28: Fargo | AD28: 950930
D29: 2020 | E29: Jan | F29: 23234 | G29: 111865 | Z29: Maryland | AA29: 951134 | AC29: Hartford | AD29: 1646448
D30: 2021 | E30: Oct | F30: 13176 | G30: 64633 | Z30: Massachusetts | AA30: 1578435 | AC30: Honolulu | AD30: 2734457
E31: Nov | F31: 95853 | G31: 458612 | Z31: Michigan | AA31: 2287283 | AC31: Indianapolis | AD31: 1084723
E32: Dec | F32: 123187 | G32: 588234 | Z32: Mississippi | AA32: 2218609 | AC32: Jackson | AD32: 2218609
Z33: Missouri | AA33: 1189515 | AC33: Knoxville | AD33: 2567190
F34: Online | G34: Outlet | X34: Top 5 States 2020 | Z34: Montana | AA34: 1930761 | AC34: Little Rock | AD34: 1802672 | AE34: Top 5 Cities 2020
D35: 2020 | E35: Nov | F35: 102780 | G35: 485104 | J35: ` | X35: =_xlfn.XLOOKUP(LARGE(AA2:AA10,1),AA2:AA10, Z2:Z10) -> New York | Z35: Nebraska | AA35: 728838 | AC35: Los Angeles | AD35: 3651288 | AE35: =_xlfn.XLOOKUP(LARGE(AD2:AD10,1),AD2:AD10, AC2:AC10) -> New York
E36: Dec | F36: 117064 | G36: 541192 | X36: =_xlfn.XLOOKUP(LARGE(AA2:AA10,2),AA2:AA10, Z2:Z10) -> Florida | Z36: New Hampshire | AA36: 2339267 | AC36: Louisville | AD36: 1241148 | AE36: =_xlfn.XLOOKUP(LARGE(AD2:AD10,2),AD2:AD10, AC2:AC10) -> Miami
D37: 2021 | E37: Jan | F37: 417799 | G37: 1981996 | X37: =_xlfn.XLOOKUP(LARGE(AA2:AA10,3),AA2:AA10, Z2:Z10) -> Texas | Z37: New Jersey | AA37: 1220446 | AC37: Manchester | AD37: 2339267 | AE37: =_xlfn.XLOOKUP(LARGE(AD2:AD10,3),AD2:AD10, AC2:AC10) -> Houston
E38: Feb | F38: 206916 | G38: 991992 | X38: =_xlfn.XLOOKUP(LARGE(AA2:AA10,4),AA2:AA10, Z2:Z10) -> Washington | Z38: New Mexico | AA38: 2824641 | AC38: Milwaukee | AD38: 948894 | AE38: =_xlfn.XLOOKUP(LARGE(AD2:AD10,4),AD2:AD10, AC2:AC10) -> Seattle
E39: Mar | F39: 14309 | G39: 70068 | X39: =_xlfn.XLOOKUP(LARGE(AA2:AA10,5),AA2:AA10, Z2:Z10) -> Nevada | Z39: New York | AA39: 2994304 | AC39: New Orleans | AD39: 3377031 | AE39: =_xlfn.XLOOKUP(LARGE(AD2:AD10,5),AD2:AD10, AC2:AC10) -> Las Vegas
X40: Top 10 States 2021 | Z40: North Carolina | AA40: 2936581 | AC40: Newark | AD40: 1220446 | AE40: Top 10 Cities 2021
...

Sheet Product Pivot
F1: Average Margin | I1: Sum of Units Sold | J1: Sum of Total Sales | K1: Average of Price per Unit | L1: Average of Margin | M1: Operating Profit | N1: Top Method | O1: Top State | P1: Top city | S1: Men's Apparel | T1: Men's Athletic Footwear | U1: Men's Street Footwear | V1: Women's Apparel | W1: Women's Athletic Footwear | X1: Women's Street Footwear | AB1: Men's Apparel | AC1: Men's Athletic Footwear | AD1: Men's Street Footwear | AE1: Women's Apparel | AF1: Women's Athletic Footwear | AG1: Women's Street Footwear | AI1: Men's Apparel | AJ1: Men's Athletic Footwear | AK1: Men's Street Footwear | AL1: Women's Apparel | AM1: Women's Athletic Footwear | AN1: Women's Street Footwear | AQ1: Products Sold | AS1: Row Labels | AT1: Products Sold | AV1: Row Labels | AW1: Average of Price per Unit | AY1: Row Labels | AZ1: Sum of Units Sold
E2: Men's Apparel | F2: 0.4132254 | H2: Men's Apparel | I2: 306683 | J2: 16520632 | K2: 50.321918 | L2: 0.4132254 | M2: 6381405.3 | N2: {=TRANSPOSE(AI5:AN5)} -> Online | O2: New York | P2: New York | Q2: 2020 | R2: Jan | S2: 5902 | T2: 7791 | U2: 11919 | V2: 8489 | W2: 6261 | X2: 7971 | Z2: 2020 | AA2: Jan | AB2: 52.083333 | AC2: 47.333333 | AD2: 42.703704 | AE2: 52.074074 | AF2: 44.666667 | AG2: 44.208333 | AH2: In-store | AI2: 85375 | AJ2: 117150 | AK2: 176030 | AL2: 120500 | AM2: 85450 | AN2: 105485 | AP2: Men's Apparel | AQ2: 306683 | AS2: Men's Apparel | AT2: 306683 | AV2: Amazon | AW2: 48.759747 | AY2: Alabama | AZ2: 63327
A3: Product | B3: Average of Price per Unit | E3: Men's Athletic Footwear | F3: 0.40270186 | H3: Men's Athletic Footwear | I3: 435526 | J3: 20577180 | K3: 43.779503 | L3: 0.40270186 | M3: 7437456.9 | N3: Online | O3: Texas | P3: New York | R3: Feb | S3: 5400 | T3: 7694 | U3: 7205 | V3: 4641 | W3: 6071 | X3: 6835 | AA3: Feb | AB3: 58.444444 | AC3: 55.47619 | AD3: 54.333333 | AE3: 65.533333 | AF3: 50.52381 | AG3: 51.333333 | AH3: Online | AI3: 117766 | AJ3: 163855 | AK3: 225121 | AL3: 163937 | AM3: 120755 | AN3: 147659 | AP3: Albany | AQ3: 8150 | AS3: Alabama | AT3: 7285 | AV3: Foot Locker | AW3: 44.784983 | AY3: Alaska | AZ3: 30815
A4: Men's Apparel | B4: 50.321918 | E4: Men's Street Footwear | F4: 0.44613043 | H4: Men's Street Footwear | I4: 593320 | J4: 27680769 | K4: 44.236646 | L4: 0.44613043 | M4: 11629046 | N4: Online | O4: New York | P4: New York | R4: Mar | S4: 5320 | T4: 8652 | U4: 10022 | V4: 8348 | W4: 6955 | X4: 7675 | AA4: Mar | AB4: 55.380952 | AC4: 49.409091 | AD4: 46.590909 | AE4: 57.5 | AF4: 45.681818 | AG4: 45.909091 | AH4: Outlet | AI4: 103542 | AJ4: 154521 | AK4: 192169 | AL4: 149390 | AM4: 111031 | AN4: 139125 | AP4: Albuquerque | AQ4: 6244 | AS4: Alaska | AT4: 3211 | AV4: Kohl's | AW4: 44.608738 | AY4: Arizona | AZ4: 46919
A5: Men's Athletic Footwear | B5: 43.779503 | E5: Women's Apparel | F5: 0.44131841 | H5: Women's Apparel | I5: 433827 | J5: 23870985 | K5: 51.600746 | L5: 0.44131841 | M5: 9685220.6 | N5: Online | O5: New York | P5: New York | R5: Apr | S5: 8258 | T5: 9410 | U5: 11960 | V5: 9995 | W5: 7125 | X5: 7961 | AA5: Apr | AB5: 60.913043 | AC5: 57.181818 | AD5: 56.409091 | AE5: 64.956522 | AF5: 53.7 | AG5: 55 | AH5: Top Method | AI5: =_xlfn.XLOOKUP(MAX(AI2:AI4),AI2:AI4,$AH$2:$AH$4) -> Online | AJ5: =_xlfn.XLOOKUP(MAX(AJ2:AJ4),AJ2:AJ4,$AH$2:$AH$4) -> Online | AK5: =_xlfn.XLOOKUP(MAX(AK2:AK4),AK2:AK4,$AH$2:$AH$4) -> Online | AL5: =_xlfn.XLOOKUP(MAX(AL2:AL4),AL2:AL4,$AH$2:$AH$4) -> Online | AM5: =_xlfn.XLOOKUP(MAX(AM2:AM4),AM2:AM4,$AH$2:$AH$4) -> Online | AN5: =_xlfn.XLOOKUP(MAX(AN2:AN4),AN2:AN4,$AH$2:$AH$4) -> Online | AP5: Anchorage | AQ5: 3211 | AS5: Arizona | AT5: 5233 | AV5: Sports Direct | AW5: 42.046752 | AY5: Arkansas | AZ5: 48468
A6: Men's Street Footwear | B6: 44.236646 | E6: Women's Athletic Footwear | F6: 0.42435866 | H6: Women's Athletic Footwear | I6: 317236 | J6: 14315521 | K6: 41.112702 | L6: 0.42435866 | M6: 5597822.4 | N6: Online | O6: New York | P6: New York | R6: May | S6: 6064 | T6: 6372 | U6: 6949 | V6: 6057 | W6: 4844 | X6: 5419 | AA6: May | AB6: 63.555556 | AC6: 57 | AD6: 56 | AE6: 67.705882 | AF6: 56.2 | AG6: 54.4 | AP6: Atlanta | AQ6: 6583 | AS6: Arkansas | AT6: 6354 | AV6: Walmart | AW6: 47.183706 | AY6: California | AZ6: 163284
A7: Women's Apparel | B7: 51.600746 | E7: Women's Street Footwear | F7: 0.410199 | H7: Women's Street Footwear | I7: 392269 | J7: 17201563 | K7: 40.252488 | L7: 0.410199 | M7: 6494016.8 | N7: Online | O7: Texas | P7: New York | R7: Jun | S7: 1499 | T7: 2880 | U7: 3800 | V7: 2948 | W7: 2202 | X7: 2940 | AA7: Jun | AB7: 66.2 | AC7: 64 | AD7: 57.1 | AE7: 73.4 | AF7: 61.6 | AG7: 64.9 | AP7: Baltimore | AQ7: 1951 | AS7: California | AT7: 22543 | AV7: West Gear | AW7: 46.737995 | AY7: Colorado | AZ7: 41378
A8: Women's Athletic Footwear | B8: 41.112702 | F8: Average unit price | R8: Jul | S8: 4609 | T8: 6881 | U8: 9368 | V8: 6849 | W8: 5017 | X8: 5495 | AA8: Jul | AB8: 61.375 | AC8: 56.875 | AD8: 50.380952 | AE8: 62.210526 | AF8: 55.75 | AG8: 53.9375 | AP8: Billings | AQ8: 4899 | AS8: Colorado | AT8: 4793 | AY8: Connecticut | AZ8: 34696
A9: Women's Street Footwear | B9: 40.252488 | E9: Men's Apparel | F9: 50.321918 | R9: Aug | S9: 8110 | T9: 12685 | U9: 11492 | V9: 10955 | W9: 8670 | X9: 10395 | AA9: Aug | AB9: 47.434783 | AC9: 42.5 | AD9: 35.380952 | AE9: 44.826087 | AF9: 39.869565 | AG9: 36.521739 | AP9: Birmingham | AQ9: 7285 | AS9: Connecticut | AT9: 4005 | AY9: Delaware | AZ9: 30275
A10: Total Result | B10: 45.216625 | E10: Men's Athletic Footwear | F10: 43.779503 | H10: Men's Apparel | I10: Men's Athletic Footwear | J10: Men's Street Footwear | K10: Women's Apparel | L10: Women's Athletic Footwear | M10: Women's Street Footwear | R10: Sep | S10: 6888 | T10: 7004 | U10: 8163 | V10: 8603 | W10: 6975 | X10: 8492 | AA10: Sep | AB10: 49 | AC10: 47.142857 | AD10: 51.142857 | AE10: 54.941176 | AF10: 44.352941 | AG10: 45.588235 | AP10: Boise | AQ10: 7226 | AS10: Delaware | AT10: 3609 | AY10: Florida | AZ10: 133430
E11: Men's Street Footwear | F11: 44.236646 | G11: Amazon | H11: 54.878981 | I11: 47.163522 | J11: 50.987421 | K11: 54.207547 | L11: 43.727848 | M11: 41.547771 | R11: Oct | S11: 4284 | T11: 4704 | U11: 5921 | V11: 5569 | W11: 4280 | X11: 5409 | AA11: Oct | AB11: 46.714286 | AC11: 39.714286 | AD11: 40.714286 | AE11: 49.5 | AF11: 41.214286 | AG11: 38.5625 | AP11: Boston | AQ11: 3517 | AS11: Florida | AT11: 18657 | AY11: Georgia | AZ11: 56391
E12: Women's Apparel | F12: 51.600746 | G12: Foot Locker | H12: 50.614319 | I12: 43.074661 | J12: 45.142539 | K12: 51.203233 | L12: 40.045249 | M12: 38.819635 | R12: Nov | S12: 2420 | T12: 4805 | U12: 6921 | V12: 3888 | W12: 2482 | X12: 4636 | AA12: Nov | AB12: 49.25 | AC12: 44.421053 | AD12: 42.421053 | AE12: 47.0625 | AF12: 39 | AG12: 41.421053 | AP12: Burlington | AQ12: 4607 | AS12: Georgia | AT12: 6583 | AY12: Hawaii | AZ12: 40375
E13: Women's Athletic Footwear | F13: 41.112702 | G13: Kohl's | H13: 49.438596 | I13: 43.47093 | J13: 42.284884 | K13: 51.97093 | L13: 40.368421 | M13: 40.122093 | R13: Dec | S13: 2473 | T13: 2882 | U13: 5466 | V13: 3866 | W13: 3295 | X13: 2563 | AA13: Dec | AB13: 50.3125 | AC13: 44.384615 | AD13: 47.375 | AE13: 54.75 | AF13: 42.666667 | AG13: 41.692308 | AP13: Charleston, SC | AQ13: 10780 | AS13: Hawaii | AT13: 4666 | AY13: Idaho | AZ13: 63827
E14: Women's Street Footwear | F14: 40.252488 | G14: Sports Direct | H14: 46.943953 | I14: 39.985163 | J14: 39.391045 | K14: 47.768328 | L14: 39.849112 | M14: 38.292398 | Q14: 2021 | R14: Jan | S14: 21895 | T14: 32946 | U14: 41055 | V14: 30823 | W14: 21703 | X14: 30877 | Z14: 2021 | AA14: Jan | AB14: 45.423729 | AC14: 39.041322 | AD14: 35.288136 | AE14: 40.838983 | AF14: 35.432203 | AG14: 33.279661 | AO14: TOP 5 Cities | AP14: Charleston, WV | AQ14: 3697 | AS14: Idaho | AT14: 7226 | AY14: Illinois | AZ14: 25407
G15: Walmart | H15: 49.451327 | I15: 47.298077 | J15: 47 | K15: 53.915888 | L15: 41.72549 | M15: 43.010101 | R15: Feb | S15: 19023 | T15: 25482 | U15: 41223 | V15: 26838 | W15: 17710 | X15: 25837 | AA15: Feb | AB15: 44.675926 | AC15: 37.785714 | AD15: 34.642857 | AE15: 37.436364 | AF15: 33.814815 | AG15: 31.642857 | AO15: =_xlfn.XLOOKUP(LARGE(AQ3:AQ56, 1), AQ3:AQ56, AP3:AP56) -> New York | AP15: Charlotte | AQ15: 9080 | AS15: Illinois | AT15: 2480 | AY15: Indiana | AZ15: 26332
G16: West Gear | H16: 51.727735 | I16: 45.646465 | J16: 44.743655 | K16: 53.502525 | L16: 42.506329 | M16: 42.3625 | R16: Mar | S16: 15742 | T16: 24032 | U16: 38352 | V16: 23298 | W16: 17650 | X16: 24914 | AA16: Mar | AB16: 43.80531 | AC16: 35.745455 | AD16: 32.236364 | AE16: 36.463636 | AF16: 33.521739 | AG16: 30.442478 | AO16: =_xlfn.XLOOKUP(LARGE(AQ3:AQ56, 2), AQ3:AQ56, AP3:AP56) -> San Francisco | AP16: Cheyenne | AQ16: 6983 | AS16: Indiana | AT16: 2979 | AU16: TOP 5 States | AY16: Iowa | AZ16: 23446
R17: Apr | S17: 17821 | T17: 26082 | U17: 41112 | V17: 30369 | W17: 19719 | X17: 26614 | AA17: Apr | AB17: 45.372881 | AC17: 38.305085 | AD17: 36.177966 | AE17: 44.082645 | AF17: 33.194915 | AG17: 32.652542 | AO17: =_xlfn.XLOOKUP(LARGE(AQ3:AQ56, 3), AQ3:AQ56, AP3:AP56) -> Houston | AP17: Chicago | AQ17: 2480 | AS17: Iowa | AT17: 2494 | AU17: =_xlfn.XLOOKUP(LARGE(AT3:AT52, 1), AT3:AT52, AS3:AS52) -> New York | AY17: Kansas | AZ17: 29463
R18: May | S18: 22533 | T18: 29368 | U18: 44221 | V18: 32817 | W18: 22623 | X18: 27338 | AA18: May | AB18: 47.598361 | AC18: 43.475 | AD18: 45.170732 | AE18: 53.2 | AF18: 40.366667 | AG18: 40.808333 | AO18: =_xlfn.XLOOKUP(LARGE(AQ3:AQ56, 4), AQ3:AQ56, AP3:AP56) -> Miami | AP18: Columbus | AQ18: 6721 | AS18: Kansas | AT18: 3498 | AU18: =_xlfn.XLOOKUP(LARGE(AT3:AT52, 2), AT3:AT52, AS3:AS52) -> California | AY18: Kentucky | AZ18: 28664
I19: Men's Apparel | J19: Men's Athletic Footwear | K19: Men's Street Footwear | L19: Women's Apparel | M19: Women's Athletic Footwear | N19: Women's Street Footwear | R19: Jun | S19: 19460 | T19: 26952 | U19: 41675 | V19: 31230 | W19: 20828 | X19: 24600 | AA19: Jun | AB19: 53.963964 | AC19: 44.053571 | AD19: 45.954955 | AE19: 59.63964 | AF19: 42.9375 | AG19: 42.473214 | AO19: =_xlfn.XLOOKUP(LARGE(AQ3:AQ56, 5), AQ3:AQ56, AP3:AP56) -> Charleston, SC | AP19: Dallas | AQ19: 8312 | AS19: Kentucky | AT19: 3179 | AU19: =_xlfn.XLOOKUP(LARGE(AT3:AT52, 3), AT3:AT52, AS3:AS52) -> Texas | AY19: Louisiana | AZ19: 57615
G20: 2020 | H20: Jan | I20: 326362 | J20: 377583 | K20: 544120 | L20: 437588 | M20: 282431 | N20: 344662 | R20: Jul | S20: 23665 | T20: 30992 | U20: 44625 | V20: 32759 | W20: 22101 | X20: 26339 | AA20: Jul | AB20: 54.513514 | AC20: 50.415929 | AD20: 53.495495 | AE20: 60.884956 | AF20: 45.711712 | AG20: 46.603604 | AP20: Denver | AQ20: 4793 | AS20: Louisiana | AT20: 6792 | AU20: =_xlfn.XLOOKUP(LARGE(AT3:AT52, 4), AT3:AT52, AS3:AS52) -> Florida | AY20: Maine | AZ20: 22410
H21: Feb | I21: 326016 | J21: 438053 | K21: 410476 | L21: 302611 | M21: 309938 | N21: 353719 | R21: Aug | S21: 22603 | T21: 37521 | U21: 48094 | V21: 31150 | W21: 24749 | X21: 31297 | AA21: Aug | AB21: 48.596639 | AC21: 46.754237 | AD21: 48.008264 | AE21: 51.210084 | AF21: 41.91453 | AG21: 42.441667 | AP21: Des Moines | AQ21: 2494 | AS21: Maine | AT21: 2215 | AU21: =_xlfn.XLOOKUP(LARGE(AT3:AT52, 5), AT3:AT52, AS3:AS52) -> South Carolina | AY21: Maryland | AZ21: 20818
H22: Mar | I22: 308592 | J22: 449299 | K22: 515790 | L22: 501368 | M22: 334077 | N22: 365076 | R22: Sep | S22: 22219 | T22: 34374 | U22: 42335 | V22: 31510 | W22: 22841 | X22: 29146 | AA22: Sep | AB22: 43.677686 | AC22: 43.206612 | AD22: 43.355372 | AE22: 45.666667 | AF22: 36.231405 | AG22: 36.77686 | AP22: Detroit | AQ22: 6976 | AS22: Maryland | AT22: 1951 | AY22: Massachusetts | AZ22: 32895
H23: Apr | I23: 502349 | J23: 538944 | K23: 688594 | L23: 651581 | M23: 379044 | N23: 432569 | R23: Oct | S23: 18837 | T23: 29266 | U23: 36279 | V23: 27285 | W23: 19194 | X23: 21973 | AA23: Oct | AB23: 48.641667 | AC23: 40.439024 | AD23: 43.975 | AE23: 52.35 | AF23: 40.830645 | AG23: 40.61157 | AP23: Fargo | AQ23: 2365 | AS23: Massachusetts | AT23: 3517 | AY23: Michigan | AZ23: 50095
H24: May | I24: 391951 | J24: 370195 | K24: 411262 | L24: 417820 | M24: 274544 | N24: 298992 | R24: Nov | S24: 19631 | T24: 25902 | U24: 34104 | V24: 26710 | W24: 20984 | X24: 22019 | AA24: Nov | AB24: 60 | AC24: 41.991228 | AD24: 47.421053 | AE24: 63.087719 | AF24: 46.931034 | AG24: 41.87931 | AP24: Hartford | AQ24: 4005 | AS24: Michigan | AT24: 6976 | AY24: Minnesota | AZ24: 20838
H25: Jun | I25: 104088 | J25: 189717 | K25: 224950 | L25: 227368 | M25: 141376 | N25: 196695 | R25: Dec | S25: 22027 | T25: 30849 | U25: 41059 | V25: 28830 | W25: 22957 | X25: 25524 | AA25: Dec | AB25: 60.088496 | AC25: 52.946429 | AD25: 58.660714 | AE25: 64.736364 | AF25: 51.790909 | AG25: 51.654545 | AP25: Honolulu | AQ25: 4666 | AS25: Minnesota | AT25: 1912 | AY25: Mississippi | AZ25: 56814
H26: Jul | I26: 294696 | J26: 393292 | K26: 484221 | L26: 428591 | M26: 278525 | N26: 303063 | AP26: Houston | AQ26: 11426 | AS26: Mississippi | AT26: 7753 | AY26: Missouri | AZ26: 36404
H27: Aug | I27: 402807 | J27: 559961 | K27: 431109 | L27: 502008 | M27: 356600 | N27: 389145 | AP27: Indianapolis | AQ27: 2979 | AS27: Missouri | AT27: 4587 | AY27: Montana | AZ27: 42713
H28: Sep | I28: 358849 | J28: 347893 | K28: 445151 | L28: 496693 | M28: 322188 | N28: 396912 | AP28: Jackson | AQ28: 7753 | AS28: Montana | AT28: 4899 | AY28: Nebraska | AZ28: 19154
H29: Oct | I29: 216862 | J29: 201790 | K29: 259287 | L29: 308771 | M29: 201270 | N29: 240589 | AP29: Knoxville | AQ29: 7737 | AS29: Nebraska | AT29: 1455 | AY29: Nevada | AZ29: 51831
H30: Nov | I30: 123313 | J30: 229246 | K30: 299514 | L30: 188094 | M30: 110819 | N30: 217064 | AP30: Las Vegas | AQ30: 6041 | AS30: Nevada | AT30: 6041 | AY30: New Hampshire | AZ30: 40812
H31: Dec | I31: 139454 | J31: 141614 | K31: 276546 | L31: 230214 | M31: 164080 | N31: 127294 | AP31: Little Rock | AQ31: 6354 | AS31: New Hampshire | AT31: 5048 | AY31: New Jersey | AZ31: 26540
G32: 2021 | H32: Jan | I32: 1074431 | J32: 1410053 | K32: 1560200 | L32: 1385615 | M32: 864906 | N32: 1136816 | AP32: Los Angeles | AQ32: 10536 | AS32: New Jersey | AT32: 2942 | AY32: New Mexico | AZ32: 52633
H33: Feb | I33: 915792 | J33: 1047589 | K33: 1500934 | L33: 1099169 | M33: 670285 | N33: 889271 | AP33: Louisville | AQ33: 3179 | AS33: New Mexico | AT33: 6244 | AY33: New York | AZ33: 169140
H34: Mar | I34: 708175 | J34: 899022 | K34: 1273838 | L34: 890825 | M34: 640024 | N34: 808898 | AP34: Manchester | AQ34: 5048 | AS34: New York | AT34: 25168 | AY34: North Carolina | AZ34: 62936
H35: Apr | I35: 822878 | J35: 1060055 | K35: 1533503 | L35: 1392273 | M35: 713497 | N35: 976133 | AP35: Miami | AQ35: 11299 | AS35: North Carolina | AT35: 9080 | AY35: North Dakota | AZ35: 22781
H36: May | I36: 1141146 | J36: 1348188 | K36: 2067956 | L36: 1839057 | M36: 985391 | N36: 1195218 | AP36: Milwaukee | AQ36: 2546 | AS36: North Dakota | AT36: 2365 | AY36: Ohio | AZ36: 47781
H37: Jun | I37: 1140932 | J37: 1292886 | K37: 2012344 | L37: 2050292 | M37: 1016812 | N37: 1205687 | AP37: Minneapolis | AQ37: 1912 | AS37: Ohio | AT37: 6721 | AY37: Oklahoma | AZ37: 40459
H38: Jul | I38: 1434600 | J38: 1724613 | K38: 2533907 | L38: 2131234 | M38: 1147834 | N38: 1395843 | AP38: New Orleans | AQ38: 6792 | AS38: Oklahoma | AT38: 4982 | AY38: Oregon | AZ38: 50536
H39: Aug | I39: 1169902 | J39: 1870916 | K39: 2468905 | L39: 1622811 | M39: 1089827 | N39: 1429235 | AP39: New York | AQ39: 17018 | AS39: Oregon | AT39: 5731 | AY39: Pennsylvania | AZ39: 27662
H40: Sep | I40: 1010730 | J40: 1568600 | K40: 1912055 | L40: 1510183 | M40: 869291 | N40: 1167039 | AP40: Newark | AQ40: 2942 | AS40: Pennsylvania | AT40: 2559 | AY40: Rhode Island | AZ40: 27473
...

Sheet Retailer Pivot
G1: Amazon | H1: Foot Locker | I1: Kohl's | J1: Walmart | K1: Sports Direct | L1: West Gear | M1: Max | N1: Sum | O1: Top 5 month 2020 | Q1: Top 5 month 2021 | S1: Total profit | V1: In-store | W1: Online | X1: Outlet | Z1: Amazon | AA1: Foot Locker | AB1: Kohl's | AC1: Sports Direct | AD1: Walmart | AE1: West Gear | AF1: Units Sold | AI1: Amazon | AJ1: Foot Locker | AK1: Kohl's | AL1: Sports Direct | AM1: Walmart | AN1: West Gear | AP1: Amazon | AS1: Foot Locker | AV1: Kohl's | AY1: Sports Direct | BB1: Walmart | BE1: West Gear
E2: 2020 | F2: Jan | H2: 1399680 | L2: 913066 | M2: =MAX(G2:L2) -> 1399680 | N2: =SUM(G2:L2) -> 2312746 | O2: =+_xlfn.XLOOKUP(P2, $M$2:$M$13, $F$2:$F$13) -> Apr | P2: =LARGE(M2:M13, 1) -> 1866127 | Q2: =_xlfn.XLOOKUP(R2, $M$14:$M$25, $F$14:$F$25) -> Sep | R2: =LARGE($M$14:$M$25, 1) -> 4005860 | S2: West Gear | T2: 12196891 | U2: Amazon | V2: 40050 | W2: 97859 | X2: 60081 | Y2: In-store | Z2: 40050 | AA2: 160745 | AB2: 63370 | AC2: 111370 | AD2: 20700 | AE2: 293755 | AF2: Amazon | AG2: 197990 | AH2: Men's Apparel | AI2: 24062 | AJ2: 71543 | AK2: 36080 | AL2: 67160 | AM2: 30506 | AN2: 77332 | AP2: Anchorage | AQ2: 26749 | AS2: Anchorage | AT2: 4066 | AV2: Albany | AW2: 10053 | AY2: Albuquerque | AZ2: 8881 | BB2: Honolulu | BC2: 12373 | BE2: Albany | BF2: 47133
A3: Product | B3: Sum of Units Sold | F3: Feb | H3: 714912 | L3: 1425901 | M3: =MAX(G3:L3) -> 1425901 | N3: =SUM(G3:L3) -> 2140813 | O3: =+_xlfn.XLOOKUP(P3, $M$2:$M$13, $F$2:$F$13) -> Jul | P3: =LARGE(M2:M13, 2) -> 1602375 | Q3: =_xlfn.XLOOKUP(R3, $M$14:$M$25, $F$14:$F$25) -> Dec | R3: =LARGE($M$14:$M$25, 2) -> 3512277 | S3: Foot Locker | T3: 11317027 | U3: Foot Locker | V3: 160745 | W3: 258150 | X3: 185474 | Y3: Online | Z3: 97859 | AA3: 258150 | AB3: 112721 | AC3: 216897 | AD3: 68621 | AE3: 184845 | AF3: Foot Locker | AG3: 604369 | AH3: Men's Athletic Footwear | AI3: 31987 | AJ3: 103767 | AK3: 51012 | AL3: 100203 | AM3: 37157 | AN3: 111400 | AP3: Birmingham | AQ3: 1674 | AS3: Atlanta | AT3: 14977 | AV3: Albuquerque | AW3: 43752 | AY3: Atlanta | AZ3: 41414 | BB3: Houston | BC3: 65072 | BE3: Baltimore | BF3: 5647
A4: Men's Apparel | B4: 306683 | F4: Mar | H4: 1470219 | L4: 1003983 | M4: =MAX(G4:L4) -> 1470219 | N4: =SUM(G4:L4) -> 2474202 | O4: =+_xlfn.XLOOKUP(P4, $M$2:$M$13, $F$2:$F$13) -> Mar | P4: =LARGE(M2:M13, 3) -> 1470219 | Q4: =_xlfn.XLOOKUP(R4, $M$14:$M$25, $F$14:$F$25) -> Jan | R4: =LARGE($M$14:$M$25, 3) -> 3359940 | S4: Sports Direct | T4: 10641609 | U4: Kohl's | V4: 63370 | W4: 112721 | X4: 111284 | Y4: Outlet | Z4: 60081 | AA4: 185474 | AB4: 111284 | AC4: 229373 | AD4: 116904 | AE4: 146662 | AF4: Kohl's | AG4: 287375 | AH4: Men's Street Footwear | AI4: 54883 | AJ4: 159081 | AK4: 66844 | AL4: 124879 | AM4: 41980 | AN4: 145653 | AP4: Boston | AQ4: 11763 | AS4: Baltimore | AT4: 9322 | AV4: Billings | AW4: 39656 | AY4: Baltimore | AZ4: 5849 | BB4: Jackson | BC4: 18298 | BE4: Boise | BF4: 23539
A5: Men's Athletic Footwear | B5: 435526 | F5: Apr | H5: 98112 | J5: 1228842 | L5: 1866127 | M5: =MAX(G5:L5) -> 1866127 | N5: =SUM(G5:L5) -> 3193081 | O5: =+_xlfn.XLOOKUP(P5, $M$2:$M$13, $F$2:$F$13) -> Feb | P5: =LARGE(M2:M13, 4) -> 1425901 | Q5: =_xlfn.XLOOKUP(R5, $M$14:$M$25, $F$14:$F$25) -> Jul | R5: =LARGE($M$14:$M$25, 4) -> 3309411 | S5: Kohl's | T5: 5182260.1 | U5: Sports Direct | V5: 111370 | W5: 216897 | X5: 229373 | Y5: Top method | Z5: =_xlfn.XLOOKUP(MAX(Z2:Z4), Z2:Z4,$Y$2:$Y$4) -> Online | AA5: =_xlfn.XLOOKUP(MAX(AA2:AA4), AA2:AA4,$Y$2:$Y$4) -> Online | AB5: =_xlfn.XLOOKUP(MAX(AB2:AB4), AB2:AB4,$Y$2:$Y$4) -> Online | AC5: =_xlfn.XLOOKUP(MAX(AC2:AC4), AC2:AC4,$Y$2:$Y$4) -> Outlet | AD5: =_xlfn.XLOOKUP(MAX(AD2:AD4), AD2:AD4,$Y$2:$Y$4) -> Outlet | AE5: =_xlfn.XLOOKUP(MAX(AE2:AE4), AE2:AE4,$Y$2:$Y$4) -> In-store | AF5: Sports Direct | AG5: 557640 | AH5: Women's Apparel | AI5: 35885 | AJ5: 104489 | AK5: 49012 | AL5: 99390 | AM5: 38002 | AN5: 107049 | AP5: Burlington | AQ5: 36476 | AS5: Boise | AT5: 22662 | AV5: Cheyenne | AW5: 43701 | AY5: Billings | AZ5: 3057 | BB5: Little Rock | BC5: 33743 | BE5: Burlington | BF5: 2209
A6: Men's Street Footwear | B6: 593320 | F6: May | H6: 137761 | J6: 633473 | K6: 263485 | L6: 1130045 | M6: =MAX(G6:L6) -> 1130045 | N6: =SUM(G6:L6) -> 2164764 | O6: =+_xlfn.XLOOKUP(P6, $M$2:$M$13, $F$2:$F$13) -> Jan | P6: =LARGE(M2:M13, 5) -> 1399680 | Q6: =_xlfn.XLOOKUP(R6, $M$14:$M$25, $F$14:$F$25) -> Jun | R6: =LARGE($M$14:$M$25, 5) -> 2926524 | S6: Amazon | T6: 3984432.1 | U6: Walmart | V6: 20700 | W6: 68621 | X6: 116904 | AF6: Walmart | AG6: 206225 | AH6: Women's Athletic Footwear | AI6: 22544 | AJ6: 73104 | AK6: 38517 | AL6: 73697 | AM6: 26835 | AN6: 82539 | AP6: Charlotte | AQ6: 10350 | AS6: Charleston, SC | AT6: 60177 | AV6: Los Angeles | AW6: 74543 | AY6: Birmingham | AZ6: 61653 | BB6: New York | BC6: 34726 | BE6: Charleston, WV | BF6: 21669
A7: Women's Apparel | B7: 433827 | F7: Jun | L7: 1084194 | M7: =MAX(G7:L7) -> 1084194 | N7: =SUM(G7:L7) -> 1084194 | S7: Walmart | T7: 3902748.9 | U7: West Gear | V7: 293755 | W7: 184845 | X7: 146662 | AF7: West Gear | AG7: 625262 | AH7: Women's Street Footwear | AI7: 28629 | AJ7: 92385 | AK7: 45910 | AL7: 92311 | AM7: 31745 | AN7: 101289 | AP7: Columbus | AQ7: 44925 | AS7: Charleston, WV | AT7: 8204 | AV7: Minneapolis | AW7: 2214 | AY7: Boise | AZ7: 17626 | BB7: Orlando | BC7: 42013 | BE7: Columbus | BF7: 2856
A8: Women's Athletic Footwear | B8: 317236 | F8: Jul | J8: 106040 | K8: 473973 | L8: 1602375 | M8: =MAX(G8:L8) -> 1602375 | N8: =SUM(G8:L8) -> 2182388 | AH8: Most popular Product | AI8: =_xlfn.XLOOKUP(MAX(AI2:AI7), AI2:AI7, $AH$2:$AH$7) -> Men's Street Footwear | AJ8: =_xlfn.XLOOKUP(MAX(AJ2:AJ7), AJ2:AJ7, $AH$2:$AH$7) -> Men's Street Footwear | AK8: =_xlfn.XLOOKUP(MAX(AK2:AK7), AK2:AK7, $AH$2:$AH$7) -> Men's Street Footwear | AL8: =_xlfn.XLOOKUP(MAX(AL2:AL7), AL2:AL7, $AH$2:$AH$7) -> Men's Street Footwear | AM8: =_xlfn.XLOOKUP(MAX(AM2:AM7), AM2:AM7, $AH$2:$AH$7) -> Men's Street Footwear | AN8: =_xlfn.XLOOKUP(MAX(AN2:AN7), AN2:AN7, $AH$2:$AH$7) -> Men's Street Footwear | AP8: Louisville | AQ8: 19272 | AS8: Cheyenne | AT8: 6527 | AV8: Newark | AW8: 17741 | AY8: Boston | AZ8: 21132 | BB8: States | BE8: Denver | BF8: 41378
A9: Women's Street Footwear | B9: 392269 | F9: Aug | H9: 778120 | J9: 1155962 | K9: 365618 | L9: 341930 | M9: =MAX(G9:L9) -> 1155962 | N9: =SUM(G9:L9) -> 2641630 | AO9: Total cities | AP9: Manchester | AQ9: 26088 | AR9: Total cities | AS9: Chicago | AT9: 22212 | AU9: Total cities | AV9: Oklahoma City | AW9: 12778 | AX9: Total cities | AY9: Charleston, SC | AZ9: 12433 | BA9: Total cities | BB9: Arkansas | BC9: 33743 | BD9: Total cities | BE9: Des Moines | BF9: 7658
A10: Total Result | B10: 2478861 | F10: Sep | H10: 296177 | J10: 866702 | K10: 323035 | L10: 881772 | M10: =MAX(G10:L10) -> 881772 | N10: =SUM(G10:L10) -> 2367686 | R10: Units sold | S10: Total Sales | T10: Total profit | U10: Average price per Unit | V10: Average Margin | W10: Top method | X10: Most popular Product | Y10: Top state | Z10: Top City | AO10: =COUNTA(AP2:AP10) -> 9 | AP10: Portland, M | AQ10: 20693 | AR10: =COUNTA(AS2:AS34) -> 33 | AS10: Dallas | AT10: 1495 | AU10: =COUNTA(AV2:AV13) -> 12 | AV10: Phoenix | AW10: 8818 | AX10: =COUNTA(AY2:AY27) -> 26 | AY10: Charlotte | AZ10: 52586 | BA10: =COUNTA(BB2:BB7) -> 6 | BB10: Florida | BC10: 42013 | BD10: =COUNTA(BE2:BE25) -> 24 | BE10: Houston | BF10: 4747
F11: Oct | H11: 153373 | J11: 712956 | K11: 562240 | M11: =MAX(G11:L11) -> 712956 | N11: =SUM(G11:L11) -> 1428569 | Q11: Amazon | R11: 197990 | S11: 10096987 | T11: 3984432.1 | U11: 48.759747 | V11: 0.41787144 | W11: Online | X11: Men's Street Footwear | Y11: =_xlfn.XLOOKUP(MAX(AQ12:AQ20), AQ12:AQ20, AP12:AP20) -> Ohio | Z11: =_xlfn.XLOOKUP(MAX(AQ2:AQ10),AQ2:AQ10,AP2:AP10) -> Columbus | AO11: Total states | AP11: States | AR11: Total states | AS11: Des Moines | AT11: 15788 | AU11: Total states | AV11: San Francisco | AW11: 4245 | AX11: Total states | AY11: Chicago | AZ11: 3195 | BA11: Total states | BB11: Hawaii | BC11: 12373 | BD11: Total states | BE11: Indianapolis | BF11: 26332
F12: Nov | H12: 372083 | L12: 795967 | M12: =MAX(G12:L12) -> 795967 | N12: =SUM(G12:L12) -> 1168050 | Q12: Foot Locker | R12: 604369 | S12: 29024945 | T12: 11317027 | U12: 44.784983 | V12: 0.41793326 | W12: Online | X12: Men's Street Footwear | Y12: =_xlfn.XLOOKUP(MAX(AT36:AT68),AT36:AT68,AS36:AS68) -> New York | Z12: =_xlfn.XLOOKUP(MAX(AT2:AT34), AT2:AT34, AS2:AS34) -> New York | AO12: =COUNTA(AP12:AP20) -> 9 | AP12: Alabama | AQ12: 1674 | AR12: =COUNTA(AS36:AS68) -> 33 | AS12: Detroit | AT12: 7926 | AU12: =COUNTA(AV15:AV25) -> 11 | AV12: Wichita | AW12: 20523 | AX12: =COUNTA(AY29:AY52) -> 24 | AY12: Dallas | AZ12: 67683 | BA12: =COUNTA(BB9:BB14) -> 6 | BB12: Mississippi | BC12: 18298 | BD12: =COUNTA(BE27:BE49) -> 23 | BE12: Las Vegas | BF12: 51831
F13: Dec | H13: 328443 | I13: 92503 | L13: 658256 | M13: =MAX(G13:L13) -> 658256 | N13: =SUM(G13:L13) -> 1079202 | Q13: Kohl's | R13: 287375 | S13: 13512453 | T13: 5182260.1 | U13: 44.608738 | V13: 0.41929126 | W13: Online | X13: Men's Street Footwear | Y13: =_xlfn.XLOOKUP(MAX(AW15:AW25), AW15:AW25, AV15:AV25) -> California | Z13: =_xlfn.XLOOKUP(MAX(AW2:AW13), AW2:AW13, AV2:AV13) -> Los Angeles | AP13: Alaska | AQ13: 26749 | AS13: Fargo | AT13: 7319 | AV13: Wilmington | AW13: 9351 | AY13: Detroit | AZ13: 42169 | BB13: New York | BC13: 34726 | BE13: Little Rock | BF13: 14725
E14: 2021 | F14: Jan | G14: 517241 | H14: 1416346 | I14: 1182285 | K14: 956209 | L14: 3359940 | M14: =MAX(G14:L14) -> 3359940 | N14: =SUM(G14:L14) -> 7432021 | Q14: Sports Direct | R14: 557640 | S14: 24616622 | T14: 10641609 | U14: 42.046752 | V14: 0.44489173 | W14: Outlet | X14: Men's Street Footwear | Y14: =_xlfn.XLOOKUP(MAX(AZ29:AZ52), AZ29:AZ52, AY29:AY52) -> Texas | Z14: =_xlfn.XLOOKUP(MAX(AZ2:AZ27), AZ2:AZ27, AY2:AY27) -> Dallas | AP14: Kentucky | AQ14: 19272 | AS14: Hartford | AT14: 10483 | AV14: States | AY14: Fargo | AZ14: 15462 | BB14: Texas | BC14: 65072 | BE14: Miami | BF14: 27710
F15: Feb | G15: 609131 | H15: 1266129 | I15: 1383420 | J15: 37695 | K15: 869131 | L15: 1957534 | M15: =MAX(G15:L15) -> 1957534 | N15: =SUM(G15:L15) -> 6123040 | Q15: Walmart | R15: 206225 | S15: 10506085 | T15: 3902748.9 | U15: 47.183706 | V15: 0.40653355 | W15: Outlet | X15: Men's Street Footwear | Y15: =_xlfn.XLOOKUP(MAX(BC9:BC14), BC9:BC14,BB9:BB14) -> Texas | Z15: =_xlfn.XLOOKUP(MAX(BC2:BC7), BC2:BC7, BB2:BB7) -> Houston | AI15: =AP1 -> Amazon | AJ15: =AS1 -> Foot Locker | AK15: =AV1 -> Kohl's | AL15: =AY1 -> Sports Direct | AM15: =BB1 -> Walmart | AN15: =BE1 -> West Gear | AP15: Maine | AQ15: 20693 | AS15: Honolulu | AT15: 20888 | AV15: Arizona | AW15: 8818 | AY15: Hartford | AZ15: 24213 | BE15: Milwaukee | BF15: 23950
F16: Mar | G16: 542016 | H16: 1098400 | I16: 1324979 | J16: 67052 | K16: 1319212 | L16: 869123 | M16: =MAX(G16:L16) -> 1324979 | N16: =SUM(G16:L16) -> 5220782 | Q16: West Gear | R16: 625262 | S16: 32409558 | T16: 12196891 | U16: 46.737995 | V16: 0.41785594 | W16: In-store | X16: Men's Street Footwear | Y16: =_xlfn.XLOOKUP(MAX(BF27:BF49), BF27:BF49, BE27:BE49) -> California | Z16: =_xlfn.XLOOKUP(MAX(BF2:BF25), BF2:BF25,BE2:BE25) -> San Francisco | AH16: Number of cities | AI16: =AO10 -> 9 | AJ16: =AR10 -> 33 | AK16: =AU10 -> 12 | AL16: =AX10 -> 26 | AM16: =BA10 -> 6 | AN16: =BD10 -> 24 | AP16: Massachusetts | AQ16: 11763 | AS16: Jackson | AT16: 21221 | AV16: California | AW16: 78788 | AY16: Honolulu | AZ16: 7114 | BE16: New Orleans | BF16: 47061
F17: Apr | G17: 515112 | H17: 1046277 | I17: 1726194 | J17: 297151 | K17: 1929578 | L17: 984027 | M17: =MAX(G17:L17) -> 1929578 | N17: =SUM(G17:L17) -> 6498339 | AH17: Number of states | AI17: =AO12 -> 9 | AJ17: =AR12 -> 33 | AK17: =AU12 -> 11 | AL17: =AX12 -> 24 | AM17: =BA12 -> 6 | AN17: =BD12 -> 23 | AP17: New Hampshire | AQ17: 26088 | AS17: Knoxville | AT17: 1516 | AV17: Delaware | AW17: 9351 | AY17: Houston | AZ17: 20503 | BE17: Oklahoma City | BF17: 27681
F18: May | G18: 826771 | H18: 1666479 | I18: 2411759 | J18: 388945 | K18: 1847135 | L18: 1435867 | M18: =MAX(G18:L18) -> 2411759 | N18: =SUM(G18:L18) -> 8576956 | AP18: North Carolina | AQ18: 10350 | AS18: Los Angeles | AT18: 1841 | AV18: Kansas | AW18: 20523 | AY18: Jackson | AZ18: 17295 | BE18: Orlando | BF18: 13275
F19: Jun | G19: 980773 | H19: 2926524 | I19: 750704 | J19: 695474 | K19: 1216331 | L19: 2149147 | M19: =MAX(G19:L19) -> 2926524 | N19: =SUM(G19:L19) -> 8718953 | AP19: Ohio | AQ19: 44925 | AS19: Louisville | AT19: 9392 | AV19: Minnesota | AW19: 2214 | AY19: Knoxville | AZ19: 64561 | BE19: Philadelphia | BF19: 2616
F20: Jul | G20: 1117017 | H20: 3309411 | I20: 842411 | J20: 1099799 | K20: 1467848 | L20: 2531545 | M20: =MAX(G20:L20) -> 3309411 | N20: =SUM(G20:L20) -> 10368031 | AH20: {=TRANSPOSE(AH15:AN17)} -> 0 | AI20: Number of cities | AJ20: Number of states | AP20: Vermont | AQ20: 36476 | AS20: Manchester | AT20: 14724 | AV20: Montana | AW20: 39656 | AY20: Miami | AZ20: 20731 | BE20: Portland, M | BF20: 1717
F21: Aug | G21: 1002686 | H21: 2284198 | I21: 819066 | J21: 1057046 | K21: 2680836 | L21: 1807764 | M21: =MAX(G21:L21) -> 2680836 | N21: =SUM(G21:L21) -> 9651596 | AH21: Amazon | AI21: 9 | AJ21: 9 | AS21: Miami | AT21: 24694 | AV21: New Jersey | AW21: 17741 | AY21: New York | AZ21: 5032 | BE21: Portland, O | BF21: 50536
F22: Sep | G22: 755593 | H22: 1054530 | I22: 626186 | J22: 686844 | K22: 4005860 | L22: 908885 | M22: =MAX(G22:L22) -> 4005860 | N22: =SUM(G22:L22) -> 8037898 | AH22: Foot Locker | AI22: 33 | AJ22: 33 | AS22: Minneapolis | AT22: 18624 | AV22: New Mexico | AW22: 43752 | AY22: Newark | AZ22: 8799 | BE22: Salt Lake City | BF22: 48548
F23: Oct | G23: 832885 | H23: 1391990 | I23: 586397 | J23: 554362 | K23: 2743672 | L23: 1000883 | M23: =MAX(G23:L23) -> 2743672 | N23: =SUM(G23:L23) -> 7110189 | AH23: Kohl's | AI23: 12 | AJ23: 11 | AS23: New Orleans | AT23: 10554 | AV23: New York | AW23: 10053 | AY23: Omaha | AZ23: 2975 | BE23: San Francisco | BF23: 82655
F24: Nov | G24: 1143180 | H24: 2303504 | I24: 790890 | J24: 588604 | K24: 1542068 | L24: 1487144 | M24: =MAX(G24:L24) -> 2303504 | N24: =SUM(G24:L24) -> 7855390 | AH24: Sports Direct | AI24: 26 | AJ24: 24 | AS24: New York | AT24: 72196 | AV24: Oklahoma | AW24: 12778 | AY24: Orlando | AZ24: 5007 | BE24: Seattle | BF24: 42262
F25: Dec | G25: 1254582 | H25: 3512277 | I25: 975659 | J25: 329138 | K25: 2050391 | L25: 2214083 | M25: =MAX(G25:L25) -> 3512277 | N25: =SUM(G25:L25) -> 10336130 | AH25: Walmart | AI25: 6 | AJ25: 6 | AS25: Omaha | AT25: 16179 | AV25: Wyoming | AW25: 43701 | AY25: Providence | AZ25: 9285 | BE25: St. Louis | BF25: 7527
AH26: West Gear | AI26: 24 | AJ26: 23 | AS26: Philadelphia | AT26: 25046 | AY26: Richmond | AZ26: 11428 | BE26: States
AS27: Phoenix | AT27: 38101 | AY27: Sioux Falls | AZ27: 7557 | BE27: Arkansas | BF27: 14725
AS28: Providence | AT28: 18188 | AY28: States | BE28: California | BF28: 82655
F29: Amazon | G29: Foot Locker | H29: Kohl's | I29: Sports Direct | J29: Walmart | K29: West Gear | AR29: Richmond | AS29: 41541 | AX29: Alabama | AY29: 61653 | BD29: Colorado | BE29: 41378
E30: Midwest | F30: 44925 | G30: 141281 | H30: 62393 | I30: 74415 | K30: 68323 | AS30: Seattle | AT30: 4349 | AY30: Connecticut | AZ30: 24213 | BE30: Florida | BF30: 40985
E31: Northeast | F31: 95020 | G31: 179087 | H31: 37145 | I31: 74310 | J31: 34726 | K31: 80991 | AS31: Sioux Falls | AT31: 15416 | AY31: Florida | AZ31: 25738 | BE31: Idaho | BF31: 23539
E32: South | F32: 1674 | G32: 34786 | H32: 12778 | I32: 231695 | J32: 117113 | K32: 94214 | AS32: St. Louis | AT32: 28877 | AY32: Georgia | AZ32: 41414 | BE32: Indiana | BF32: 26332
E33: Southeast | F33: 29622 | G33: 150781 | I33: 143599 | J33: 42013 | K33: 40985 | AS33: Wichita | AT33: 8940 | AY33: Hawaii | AZ33: 7114 | BE33: Iowa | BF33: 7658
E34: West | F34: 26749 | G34: 98434 | H34: 175059 | I34: 33621 | J34: 12373 | K34: 340749 | AS34: Wilmington | AT34: 20924 | AY34: Idaho | AZ34: 17626 | BE34: Louisiana | BF34: 47061
AS35: States | AY35: Illinois | AZ35: 3195 | BE35: Maine | BF35: 1717
AS36: Alaska | AT36: 4066 | AY36: Maryland | AZ36: 5849 | BE36: Maryland | BF36: 5647
AS37: Arizona | AT37: 38101 | AY37: Massachusetts | AZ37: 21132 | BE37: Missouri | BF37: 7527
AS38: California | AT38: 1841 | AY38: Michigan | AZ38: 42169 | BE38: Nevada | BF38: 51831
AS39: Connecticut | AT39: 10483 | AY39: Mississippi | AZ39: 17295 | BE39: New York | BF39: 47133
AS40: Delaware | AT40: 20924 | AY40: Montana | AZ40: 3057 | BE40: Ohio | BF40: 2856
...

Sheet Product Pivot 2
J1: Total Sales | K1: Units Sold | L1: Average Margin | M1: Average Price | P1: Total Sales | Q1: Units Sold | R1: AverageMargin | S1: Average Price | U1: Units Sold | V1: Apparel | W1: Athletic Footwear | X1: Street Footwear | Z1: City | AA1: Units Sold | AC1: City | AD1: Units Sold | AF1: City | AG1: Units sold | AJ1: Men | AK1: Women | AM1: Men | AN1: 64778581
I2: Men | J2: 64778581 | K2: 1335529 | L2: 0.42069208 | M2: 46.1092 | O2: Apparel | P2: 40391617 | Q2: 740510 | R2: 0.42728065 | S2: 50.96173 | U2: Midwest | V2: 114739 | W2: 109928 | X2: 166670 | Z2: Apparel | AA2: 740510 | AC2: Apparel | AD2: 740510 | AF2: Men | AG2: 1335529 | AI2: Amazon | AJ2: 110932 | AK2: 87058 | AM2: Alabama | AN2: 1197827
A3: Row Labels | B3: Sum of Units Sold | I3: Woman | J3: 55388069 | K3: 1143332 | L3: 0.42529241 | M3: 44.32331 | O3: Athletic Footwear | P3: 34892701 | Q3: 752762 | R3: 0.41351679 | S3: 42.447761 | U3: Northeast | V3: 152079 | W3: 140938 | X3: 208262 | Z3: Alabama | AA3: 19113 | AC3: Albany | AD3: 18087 | AF3: Albany | AG3: 30628 | AI3: Foot Locker | AJ3: 334391 | AK3: 269978 | AM3: Alaska | AN3: 1054837
A4: Men | B4: 1335529 | O4: Street Footwear | P4: 44882332 | Q4: 985589 | R4: 0.42817589 | S4: 42.245805 | U4: South | V4: 149381 | W4: 154077 | X4: 188802 | Z4: Alaska | AA4: 8754 | AC4: Albuquerque | AD4: 14961 | AF4: Albuquerque | AG4: 27822 | AI4: Kohl's | AJ4: 153936 | AK4: 133439 | AM4: Arizona | AN4: 1172075
A5: Alabama | B5: 32129 | U5: Southeast | V5: 123224 | W5: 126421 | X5: 157355 | Z5: Arizona | AA5: 12899 | AC5: Anchorage | AD5: 8754 | AF5: Anchorage | AG5: 17630 | AI5: Sports Direct | AJ5: 292242 | AK5: 265398 | AM5: Arkansas | AN5: 1017462
A6: Alaska | B6: 17630 | U6: West | V6: 201087 | W6: 221398 | X6: 264500 | Z6: Arkansas | AA6: 15071 | AC6: Atlanta | AD6: 15490 | AF6: Atlanta | AG6: 30341 | AI6: Walmart | AJ6: 109643 | AK6: 96582 | AM6: California | AN6: 4369654
A7: Arizona | B7: 25053 | I7: In-store | J7: Online | K7: Outlet | Z7: California | AA7: 49991 | AC7: Baltimore | AD7: 5788 | AF7: Baltimore | AG7: 12386 | AI7: West Gear | AJ7: 334385 | AK7: 290877 | AM7: Colorado | AN7: 1328140
A8: Arkansas | B8: 26714 | H8: Apparel | I8: 205875 | J8: 281703 | K8: 252932 | V8: Men | W8: Women | Z8: Colorado | AA8: 11634 | AC8: Billings | AD8: 11750 | AF8: Billings | AG8: 22768 | AM8: Connecticut | AN8: 947332
A9: California | B9: 84877 | H9: Athletic Footwear | I9: 202600 | J9: 284610 | K9: 265552 | U9: Midwest | V9: 220285 | W9: 171052 | Z9: Connecticut | AA9: 10434 | AC9: Birmingham | AD9: 19113 | AF9: Birmingham | AG9: 32129 | AM9: Delaware | AN9: 862280
A10: Colorado | B10: 21883 | H10: Street Footwear | I10: 281515 | J10: 372780 | K10: 331294 | U10: Northeast | V10: 277757 | W10: 223522 | Z10: Delaware | AA10: 9138 | AC10: Boise | AD10: 19053 | AF10: Boise | AG10: 32226 | AM10: Florida | AN10: 4180571
A11: Connecticut | B11: 19593 | H11: Men | I11: 378555 | J11: 506742 | K11: 450232 | P11: Apparel | Q11: Athletic Footwear | R11: Street Footwear | U11: South | V11: 257265 | W11: 234995 | Z11: Florida | AA11: 41335 | AC11: Boston | AD11: 9469 | AF11: Boston | AG11: 18466 | AM11: Georgia | AN11: 1439752
A12: Delaware | B12: 16970 | H12: Women | I12: 311435 | J12: 432351 | K12: 399546 | O12: Amazon | P12: 59947 | Q12: 54531 | R12: 83512 | U12: Southeast | V12: 217381 | W12: 189619 | Z12: Georgia | AA12: 15490 | AC12: Burlington | AD12: 11589 | AF12: Burlington | AG12: 21663 | AM12: Hawaii | AN12: 1432969
A13: Florida | B13: 70633 | O13: Foot Locker | P13: 176032 | Q13: 176871 | R13: 251466 | U13: West | V13: 362841 | W13: 324144 | Z13: Hawaii | AA13: 11287 | AC13: Charleston, SC | AD13: 23378 | AF13: Charleston, SC | AG13: 38203 | AM13: Idaho | AN13: 1311853
A14: Georgia | B14: 30341 | O14: Kohl's | P14: 85092 | Q14: 89529 | R14: 112754 | Z14: Idaho | AA14: 19053 | AC14: Charleston, WV | AD14: 9225 | AF14: Charleston, WV | AG14: 16706 | AM14: Illinois | AN14: 706962
A15: Hawaii | B15: 21461 | O15: Sports Direct | P15: 166550 | Q15: 173900 | R15: 217190 | Z15: Illinois | AA15: 6845 | AC15: Charlotte | AD15: 20231 | AF15: Charlotte | AG15: 33234 | AM15: Indiana | AN15: 636472
A16: Idaho | B16: 32226 | O16: Walmart | P16: 68508 | Q16: 63992 | R16: 73725 | Z16: Indiana | AA16: 7786 | AC16: Cheyenne | AD16: 16057 | AF16: Cheyenne | AG16: 26670 | AM16: Iowa | AN16: 543397
A17: Illinois | B17: 14716 | O17: West Gear | P17: 184381 | Q17: 193939 | R17: 246942 | Z17: Iowa | AA17: 6806 | AC17: Chicago | AD17: 6845 | AF17: Chicago | AG17: 14716 | AM17: Kansas | AN17: 707039
A18: Indiana | B18: 15109 | Z18: Kansas | AA18: 8912 | AC18: Columbus | AD18: 15257 | AF18: Columbus | AG18: 25755 | AM18: Kentucky | AN18: 734003
A19: Iowa | B19: 13691 | Z19: Kentucky | AA19: 8259 | AC19: Dallas | AD19: 21368 | AF19: Dallas | AG19: 34999 | AM19: Louisiana | AN19: 1746264
A20: Kansas | B20: 16640 | Z20: Louisiana | AA20: 15987 | AC20: Denver | AD20: 11634 | AF20: Denver | AG20: 21883 | AM20: Maine | AN20: 666450
A21: Kentucky | B21: 16469 | H21: Apparel | I21: Athletic Footwear | J21: Street Footwear | K21: Men | L21: Women | Z21: Maine | AA21: 6298 | AC21: Des Moines | AD21: 6806 | AF21: Des Moines | AG21: 13691 | AM21: Maryland | AN21: 577931
A22: Louisiana | B22: 30942 | F22: 2020 | G22: Jan | H22: 763950 | I22: 660014 | J22: 888782 | K22: 1248065 | L22: 1064681 | Z22: Maryland | AA22: 5788 | AC22: Detroit | AD22: 15879 | AF22: Detroit | AG22: 26927 | AM22: Massachusetts | AN22: 909201
A23: Maine | B23: 13047 | G23: Feb | H23: 628627 | I23: 747991 | J23: 764195 | K23: 1174545 | L23: 966268 | Z23: Massachusetts | AA23: 9469 | AC23: Fargo | AD23: 6578 | AF23: Fargo | AG23: 13368 | AM23: Michigan | AN23: 1271895
A24: Maryland | B24: 12386 | G24: Mar | H24: 809960 | I24: 783376 | J24: 880866 | K24: 1273681 | L24: 1200521 | Z24: Michigan | AA24: 15879 | AC24: Hartford | AD24: 10434 | AF24: Hartford | AG24: 19593 | AM24: Minnesota | AN24: 539287
A25: Massachusetts | B25: 18466 | G25: Apr | H25: 1153930 | I25: 917988 | J25: 1121163 | K25: 1729887 | L25: 1463194 | Z25: Minnesota | AA25: 5635 | AC25: Honolulu | AD25: 11287 | AF25: Honolulu | AG25: 21461 | AM25: Mississippi | AN25: 1237028
A26: Michigan | B26: 26927 | G26: May | H26: 809771 | I26: 644739 | J26: 710254 | K26: 1173408 | L26: 991356 | Z26: Mississippi | AA26: 17879 | AC26: Houston | AD26: 27544 | AF26: Houston | AG26: 45404 | AM26: Missouri | AN26: 694246
A27: Minnesota | B27: 12206 | G27: Jun | H27: 331456 | I27: 331093 | J27: 421645 | K27: 518755 | L27: 565439 | Z27: Missouri | AA27: 11029 | AC27: Indianapolis | AD27: 7786 | AF27: Indianapolis | AG27: 15109 | AM27: Montana | AN27: 993905
A28: Mississippi | B28: 30804 | G28: Jul | H28: 723287 | I28: 671817 | J28: 787284 | K28: 1172209 | L28: 1010179 | P28: Total Sales | Q28: Units Sold | R28: Average Margin | S28: Average Price | Z28: Montana | AA28: 11750 | AC28: Jackson | AD28: 17879 | AF28: Jackson | AG28: 30804 | AM28: Nebraska | AN28: 443454
A29: Missouri | B29: 20105 | G29: Aug | H29: 904815 | I29: 916561 | J29: 820254 | K29: 1393877 | L29: 1247753 | O29: Men | P29: 64778581 | Q29: 1335529 | R29: 0.42069208 | S29: 46.1092 | Z29: Nebraska | AA29: 4721 | AC29: Knoxville | AD29: 20082 | AF29: Knoxville | AG29: 33586 | AM29: Nevada | AN29: 1552468
A30: Montana | B30: 22768 | G30: Sep | H30: 855542 | I30: 670081 | J30: 842063 | K30: 1151893 | L30: 1215793 | O30: Woman | P30: 55388069 | Q30: 1143332 | R30: 0.42529241 | S30: 44.32331 | Z30: Nevada | AA30: 14647 | AC30: Las Vegas | AD30: 14647 | AF30: Las Vegas | AG30: 27526 | AM30: New Hampshire | AN30: 1328401
A31: Nebraska | B31: 11547 | G31: Oct | H31: 525633 | I31: 403060 | J31: 499876 | K31: 677939 | L31: 750630 | O31: Product category | Z31: New Hampshire | AA31: 12427 | AC31: Little Rock | AD31: 15071 | AF31: Little Rock | AG31: 26714 | AM31: New Jersey | AN31: 712910
A32: Nevada | B32: 27526 | G32: Nov | H32: 311407 | I32: 340065 | J32: 516578 | K32: 652073 | L32: 515977 | O32: Apparel | P32: 40391617 | Q32: 740510 | R32: 0.42728065 | S32: 50.96173 | Z32: New Jersey | AA32: 7817 | AC32: Los Angeles | AD32: 23504 | AF32: Los Angeles | AG32: 39908 | AM32: New Mexico | AN32: 1453127
A33: New Hampshire | B33: 22718 | G33: Dec | H33: 369668 | I33: 305694 | J33: 403840 | K33: 557614 | L33: 521588 | O33: Athletic Footwear | P33: 34892701 | Q33: 752762 | R33: 0.41351679 | S33: 42.447761 | Z33: New Mexico | AA33: 14961 | AC33: Louisville | AD33: 8259 | AF33: Louisville | AG33: 16469 | AM33: New York | AN33: 4704189
A34: New Jersey | B34: 15154 | F34: 2021 | G34: Jan | H34: 2460046 | I34: 2274959 | J34: 2697016 | K34: 4044684 | L34: 3387337 | O34: Street Footwear | P34: 44882332 | Q34: 985589 | R34: 0.42817589 | S34: 42.245805 | Z34: New York | AA34: 54577 | AC34: Manchester | AD34: 12427 | AF34: Manchester | AG34: 22718 | AM34: North Carolina | AN34: 1600649
A35: New Mexico | B35: 27822 | G35: Feb | H35: 2014961 | I35: 1717874 | J35: 2390205 | K35: 3464315 | L35: 2658725 | Z35: North Carolina | AA35: 20231 | AC35: Miami | AD35: 24407 | AF35: Miami | AG35: 38497 | AM35: North Dakota | AN35: 568656
A36: New York | B36: 88934 | G36: Mar | H36: 1599000 | I36: 1539046 | J36: 2082736 | K36: 2881035 | L36: 2339747 | Z36: North Dakota | AA36: 6578 | AC36: Milwaukee | AD36: 6933 | AF36: Milwaukee | AG36: 13985 | AM36: Ohio | AN36: 1254978
A37: North Carolina | B37: 33234 | G37: Apr | H37: 2215151 | I37: 1773552 | J37: 2509636 | K37: 3416436 | L37: 3081903 | Z37: Ohio | AA37: 15257 | AC37: Minneapolis | AD37: 5635 | AF37: Minneapolis | AG37: 12206 | AM37: Oklahoma | AN37: 866105
A38: North Dakota | B38: 13368 | G38: May | H38: 2980203 | I38: 2333579 | J38: 3263174 | K38: 4557290 | L38: 4019666 | Z38: Oklahoma | AA38: 12337 | AC38: New Orleans | AD38: 15987 | AF38: New Orleans | AG38: 30942 | AM38: Oregon | AN38: 1575845
A39: Ohio | B39: 25755 | G39: Jun | H39: 3191224 | I39: 2309698 | J39: 3218031 | K39: 4446162 | L39: 4272791 | Z39: Oregon | AA39: 14042 | AC39: New York | AD39: 36490 | AF39: New York | AG39: 58306 | AM39: Pennsylvania | AN39: 872468
A40: Oklahoma | B40: 22687 | G40: Jul | H40: 3565834 | I40: 2872447 | J40: 3929750 | K40: 5693120 | L40: 4674911 | Z40: Pennsylvania | AA40: 7472 | AC40: Newark | AD40: 7817 | AF40: Newark | AG40: 15154 | AM40: Rhode Island | AN40: 713758
...

Sheet Data Sales Adidas
C2: Adidas Sales Database
B5: Retailer | C5: Retailer ID | D5: Invoice Date | E5: Region | F5: State | G5: City | H5: Product | I5: Price per Unit | J5: Units Sold | K5: Total Sales | L5: Operating Profit | M5: Operating Margin | N5: Sales Method | O5: Men/Woman | P5: Product category
B6: Foot Locker | C6: 1185732 | D6: 43831 | E6: Northeast | F6: New York | G6: New York | H6: Men's Street Footwear | I6: 50 | J6: 1200 | K6: =I6 * J6 -> 60000 | L6: =K6 *M6 -> 30000 | M6: 0.5 | N6: In-store | O6: Men | P6: =RIGHT(H6,LEN(H6) - FIND(" ", H6)) -> Street Footwear
B7: Foot Locker | C7: 1185732 | D7: 43831 | E7: Northeast | F7: Pennsylvania | G7: Philadelphia | H7: Women's Apparel | I7: 75 | J7: 275 | K7: =I7 * J7 -> 20625 | L7: =K7 *M7 -> 6187.5 | M7: 0.3 | N7: Outlet | O7: Women | P7: =RIGHT(H7,LEN(H7) - FIND(" ", H7)) -> Apparel
B8: Foot Locker | C8: 1185732 | D8: 43831 | E8: Northeast | F8: New York | G8: New York | H8: Men's Street Footwear | I8: 47 | J8: 336 | K8: =I8 * J8 -> 15792 | L8: =K8 *M8 -> 9633.12 | M8: 0.61 | N8: Online | O8: Men | P8: =RIGHT(H8,LEN(H8) - FIND(" ", H8)) -> Street Footwear
B9: Foot Locker | C9: 1185732 | D9: 43831 | E9: Northeast | F9: Pennsylvania | G9: Philadelphia | H9: Women's Apparel | I9: 68 | J9: 83 | K9: =I9 * J9 -> 5644 | L9: =K9 *M9 -> 2426.92 | M9: 0.43 | N9: Online | O9: Women | P9: =RIGHT(H9,LEN(H9) - FIND(" ", H9)) -> Apparel
B10: Foot Locker | C10: 1185732 | D10: 43831 | E10: Northeast | F10: New York | G10: New York | H10: Men's Street Footwear | I10: 34 | J10: 384 | K10: =I10 * J10 -> 13056 | L10: =K10 *M10 -> 6789.12 | M10: 0.52 | N10: Outlet | O10: Men | P10: =RIGHT(H10,LEN(H10) - FIND(" ", H10)) -> Street Footwear
B11: Foot Locker | C11: 1185732 | D11: 43831 | E11: Northeast | F11: Pennsylvania | G11: Philadelphia | H11: Women's Apparel | I11: 53 | J11: 83 | K11: =I11 * J11 -> 4399 | L11: =K11 *M11 -> 1407.68 | M11: 0.32 | N11: Outlet | O11: Women | P11: =RIGHT(H11,LEN(H11) - FIND(" ", H11)) -> Apparel
B12: Foot Locker | C12: 1185732 | D12: 43832 | E12: Northeast | F12: New York | G12: New York | H12: Men's Athletic Footwear | I12: 50 | J12: 1000 | K12: =I12 * J12 -> 50000 | L12: =K12 *M12 -> 15000 | M12: 0.3 | N12: In-store | O12: Men | P12: =RIGHT(H12,LEN(H12) - FIND(" ", H12)) -> Athletic Footwear
B13: West Gear | C13: 1128299 | D13: 43832 | E13: Northeast | F13: Pennsylvania | G13: Philadelphia | H13: Men's Street Footwear | I13: 35 | J13: 450 | K13: =I13 * J13 -> 15750 | L13: =K13 *M13 -> 6300 | M13: 0.4 | N13: Outlet | O13: Men | P13: =RIGHT(H13,LEN(H13) - FIND(" ", H13)) -> Street Footwear
B14: Foot Locker | C14: 1185732 | D14: 43832 | E14: Northeast | F14: New York | G14: New York | H14: Men's Athletic Footwear | I14: 47 | J14: 260 | K14: =I14 * J14 -> 12220 | L14: =K14 *M14 -> 5132.4 | M14: 0.42 | N14: Online | O14: Men | P14: =RIGHT(H14,LEN(H14) - FIND(" ", H14)) -> Athletic Footwear
B15: West Gear | C15: 1128299 | D15: 43832 | E15: Northeast | F15: Pennsylvania | G15: Philadelphia | H15: Men's Street Footwear | I15: 32 | J15: 122 | K15: =I15 * J15 -> 3904 | L15: =K15 *M15 -> 1991.04 | M15: 0.51 | N15: Online | O15: Men | P15: =RIGHT(H15,LEN(H15) - FIND(" ", H15)) -> Street Footwear
B16: Foot Locker | C16: 1185732 | D16: 43832 | E16: Northeast | F16: New York | G16: New York | H16: Men's Athletic Footwear | I16: 36 | J16: 320 | K16: =I16 * J16 -> 11520 | L16: =K16 *M16 -> 4032 | M16: 0.35 | N16: Outlet | O16: Men | P16: =RIGHT(H16,LEN(H16) - FIND(" ", H16)) -> Athletic Footwear
B17: West Gear | C17: 1128299 | D17: 43832 | E17: Northeast | F17: Pennsylvania | G17: Philadelphia | H17: Men's Street Footwear | I17: 27 | J17: 158 | K17: =I17 * J17 -> 4266 | L17: =K17 *M17 -> 1791.72 | M17: 0.42 | N17: Outlet | O17: Men | P17: =RIGHT(H17,LEN(H17) - FIND(" ", H17)) -> Street Footwear
... B9653: Foot Locker | C9653: 1185732 | D9653: 44561 | E9653: Northeast | F9653: Pennsylvania | G9653: Philadelphia | H9653: Men's Apparel | I9653: 46 | J9653: 56 | K9653: =I9653 * J9653 -> 2576 | L9653: =K9653 *M9653 -> 1004.64 | M9653: 0.39 | N9653: Outlet | O9653: Men | P9653: =RIGHT(H9653,LEN(H9653) - FIND(" ", H9653)) -> Apparel

Sheet Annual Analysis
A1: Adidas Sales Annual Data Analysis | F1: Year | G1: Total Sales | H1: Units sold | I1: Top method | J1: Top retailer | K1: Top profit retailer | L1: Top product category | M1: Top region | N1: Top State | O1: Top city
F2: 2020 | G2: =SUMIF('Data Sales Adidas'!D6:D9653, "<1/1/2021", 'Data Sales Adidas'!K6:K9653) -> 24237325 | H2: =SUMIF('Data Sales Adidas'!D6:D9653, "<1/1/2021", 'Data Sales Adidas'!J6:J9653) -> 462349 | I2: =_xlfn.XLOOKUP('Basic Pivot '!I8, 'Basic Pivot '!I2:I4, 'Basic Pivot '!H2:H4) -> Outlet | J2: ='Basic Pivot '!E25 -> West Gear | K2: ='Basic Pivot '!AF13 -> West Gear | L2: ='Basic Pivot '!N14 -> Men's Street Footwear | M2: ='Basic Pivot '!W12 -> West | N2: ='Basic Pivot '!Z57 -> New York | O2: ='Basic Pivot '!AC58 -> New York
F3: 2021 | G3: =SUMIF('Data Sales Adidas'!D6:D9653, ">=1/1/2021", 'Data Sales Adidas'!K6:K9653) -> 95929325 | H3: =SUMIF('Data Sales Adidas'!D7:D9654, ">=1/1/2021", 'Data Sales Adidas'!J7:J9654) -> 2016512 | I3: =_xlfn.XLOOKUP( 'Basic Pivot '!I9, 'Basic Pivot '!I5:I7, 'Basic Pivot '!H5:H7) -> Online | J3: ='Basic Pivot '!E26 -> Foot Locker | K3: ='Basic Pivot '!AF14 -> Sports Direct | L3: ='Basic Pivot '!N15 -> Men's Street Footwear | M3: ='Basic Pivot '!W13 -> West | N3: ='Basic Pivot '!Z58 -> California | O3: ='Basic Pivot '!AC59 -> Orlando
H4: This worksheet analyzes the dataset by year. It was found that the data is incomplete: in 2020, too few cities are represented, and only 2 of them occur in 2021. And even here, data is only available for 4-5 months. Therefore, it is not possible to obtain comprehensive information. Assuming that the data was collected on a specific basis, we can try to analyze the entire population.
H18: Annual sales volume change
H19: Retailer | I19: Growth in 2021
H20: Foot Locker | I20: ='Basic Pivot '!F8-'Basic Pivot '!F2 -> 17527185
H21: Kohl's | I21: ='Basic Pivot '!F9-'Basic Pivot '!F3 -> 13327447
H22: Sports Direct | I22: ='Basic Pivot '!F10-'Basic Pivot '!F4 -> 20639920
H23: Walmart | I23: ='Basic Pivot '!F11-'Basic Pivot '!F5 -> 1098135
H24: West Gear | I24: ='Basic Pivot '!F12-'Basic Pivot '!F6 -> 9002326
A49: Data is incomplete. In 2020, 9 states and cities are represented, while in 2021 - 46 and 47, respectively. 5 States and only 2 cities represented both in 2020 and 2021 years. This means that we can only effectively compare sales data for only 2 cities: Philadelphia and San Francisco | E49: Region Ranking | F49: Top 5 States 2020 | G49: Top 5 Cities 2020
E50: West | F50: New York | G50: New York
E51: Northeast | F51: Florida | G51: Miami
E52: Southeast | F52: Texas | G52: Houston
E53: South | F53: Washington | G53: Seattle
